Workbook
Name MesesEnTotal: DATEDIF(MesesEnTotal,TODAY(),"m")

Sheet Plantilla
A2: Departamento : | B2: D1
A3: Propietario : | B3: =LOOKUP(B2,#REF!,#REF!) -> #REF!
A4: Inquilino : | B4: =LOOKUP(B2,#REF!,#REF!) -> #REF!
A5: Teléfono : | B5: =LOOKUP(B2,#REF!,#REF!) -> #REF!
A6: Celular : | B6: =LOOKUP(B2,#REF!,#REF!) -> #REF!
A7: Correo : | B7: =LOOKUP(B2,#REF!,#REF!) -> #REF! | H7: Resumen
A9: Fecha | B9: Concepto | C9: Recibo | D9: Expensas | E9: Agua | F9: Column6 | G9: Total | H9: Deuda
A10: 42674 | B10: Saldo deudor al 31/10/2016 | F10: 0 | G10: =SUM(D10:F10) -> 0 | H10: =G10 -> 0
A11: 43032 | B11: Pago mantenimiento octubre/2016 | F11: 0 | G11: =SUM(D11:F11) -> 0 | H11: =H10+G11 -> 0
A12: 43069 | B12: Mantenimiento noviembre/2016 | F12: 0 | G12: =SUM(D12:F12) -> 0 | H12: =H11+G12 -> 0
A13: 42711 | B13: Pago mantenimiento noviembre/2016 | F13: 0 | G13: =SUM(D13:F13) -> 0 | H13: =H12+G13 -> 0
A14: 42735 | B14: Mantenimiento diciembre/2016 | F14: 0 | G14: =SUM(D14:F14) -> 0 | H14: =H13+G14 -> 0
A15: 42740 | B15: Pago mantenimiento diciembre/2016 | F15: 0 | G15: =SUM(D15:F15) -> 0 | H15: =H14+G15 -> 0
A16: 42766 | B16: Mantenimiento enero/2017 | F16: 0 | G16: =SUM(D16:F16) -> 0 | H16: =H15+G16 -> 0
A17: 42773 | B17: Pago mantenimiento enero/2017 | F17: 0 | G17: =SUM(D17:F17) -> 0 | H17: =H16+G17 -> 0
A18: 42794 | B18: Mantenimiento febrero/2017 | F18: 0 | G18: =SUM(D18:F18) -> 0 | H18: =H17+G18 -> 0
A19: 04/0372017 | B19: Pago mantenimiento febrero/2017 | F19: 0 | G19: =SUM(D19:F19) -> 0 | H19: =H18+G19 -> 0
A20: 42825 | B20: Mantenimiento marzo/2017 | G20: =SUM(D20:F20) -> 0 | H20: =H19+G20 -> 0
A21: 42835 | B21: Pago mantenimiento marzo/2017 | F21: 0 | G21: =SUM(D21:F21) -> 0 | H21: =H20+G21 -> 0
A22: 42855 | B22: Mantenimiento abril/2017 | G22: =SUM(D22:F22) -> 0 | H22: =H21+G22 -> 0
A23: 42860 | B23: Pago mantenimiento abril/2017 | F23: 0 | G23: =SUM(D23:F23) -> 0 | H23: =H22+G23 -> 0
A24: 42886 | B24: Mantenimiento mayo/2017 | G24: =SUM(D24:F24) -> 0 | H24: =H23+G24 -> 0
A25: 42892 | B25: Pago mantenimiento mayo/2017 | G25: =SUM(D25:F25) -> 0 | H25: =H24+G25 -> 0
A26: 42916 | B26: Mantenimiento junio/2017 | G26: =SUM(D26:F26) -> 0 | H26: =H25+G26 -> 0
B27: Pago mantenimiento junio/2017 | G27: =SUM(D27:F27) -> 0 | H27: =H26+G27 -> 0
A28: 42947 | B28: Mantenimiento julio/2017 | G28: =SUM(D28:F28) -> 0 | H28: =H27+G28 -> 0
B29: Pago mantenimiento julio/2017 | G29: =SUM(D29:F29) -> 0 | H29: =H28+G29 -> 0
A30: 42978 | B30: Mantenimiento agosto/2017 | G30: =SUM(D30:F30) -> 0 | H30: =H29+G30 -> 0
B31: Pago mantenimiento agosto/2017 | G31: =SUM(D31:F31) -> 0 | H31: =H30+G31 -> 0
A32: 43008 | B32: Mantenimiento septiembre/2017 | G32: =SUM(D32:F32) -> 0 | H32: =H31+G32 -> 0
B33: Pago mantenimiento septiembre/2017 | G33: =SUM(D33:F33) -> 0 | H33: =H32+G33 -> 0
A34: 43039 | B34: Mantenimiento octubre/2017 | G34: =SUM(D34:F34) -> 0 | H34: =H33+G34 -> 0
B35: Pago mantenimiento octubre/2017 | G35: =SUM(D35:F35) -> 0 | H35: =H34+G35 -> 0
A36: 43069 | B36: Mantenimiento noviembre/2017 | G36: =SUM(D36:F36) -> 0 | H36: =H35+G36 -> 0
B37: Pago mantenimiento noviembre/2017 | G37: =SUM(D37:F37) -> 0 | H37: =H36+G37 -> 0
A38: 43100 | B38: Mantenimiento diciembre/2017 | G38: =SUM(D38:F38) -> 0 | H38: =H37+G38 -> 0
B39: Pago mantenimiento diciembre/2017 | G39: =SUM(D39:F39) -> 0 | H39: =H38+G39 -> 0

Sheet LOCAL 01
A2: Departamento : | B2: LOCAL 01
A3: Propietario : | B3: =LOOKUP(B2,#REF!,#REF!) -> #REF!
A4: Inquilino : | B4: =LOOKUP(B2,#REF!,#REF!) -> #REF!
A5: Teléfono : | B5: =LOOKUP(B2,#REF!,#REF!) -> #REF!
A6: Celular : | B6: =LOOKUP(B2,#REF!,#REF!) -> #REF!
A7: Correo : | B7: =LOOKUP(B2,#REF!,#REF!) -> #REF! | H7: Resumen
A8: Inquilino ACTUAL:
A9: Fecha | B9: Concepto | C9: Recibo | D9: Expensas | E9: Agua | F9: Multa | G9: Total | H9: Deuda | I9: Pagado | J9: Columna1 | K9: Columna2
G10: =SUM(D10:F48) -> 117 | H10: 0 | I10: =IF(T_T134[[#This Row],[Total]]<0,T_T134[[#This Row],[Total]]*-1,0) -> 0
A11: 46052 | B11: Mantenimiento enero/2026 | D11: 90 | E11: 3 | G11: =+T_T134[[#This Row],[Expensas]]+T_T134[[#This Row],[Agua]]+T_T134[[#This Row],[Multa]] -> 93 | H11: =+H10+T_T134[[#This Row],[Total]] -> 93 | I11: =IF(T_T134[[#This Row],[Total]]<0,T_T134[[#This Row],[Total]]*-1,0) -> 0
B12: Pago mantenimiento enero/2026 | C12: 8525-8892 | D12: =-26-64 -> -90 | E12: -3 | G12: =SUM(D12:F12) -> -93 | H12: =+H11+T_T134[[#This Row],[Total]] -> 0 | I12: =IF(T_T134[[#This Row],[Total]]<0,T_T134[[#This Row],[Total]]*-1,0) -> 93
A13: 45715 | B13: Mantenimiento febrero/2025 | D13: 90 | E13: 5 | G13: =SUM(D13:F13) -> 95 | H13: =+H12+T_T134[[#This Row],[Total]] -> 95 | I13: =IF(T_T134[[#This Row],[Total]]<0,T_T134[[#This Row],[Total]]*-1,0) -> 0
B14: Pago mantenimiento febrero/2025 | C14: 8893-8892 | D14: =-64-26 -> -90 | E14: -5 | G14: =SUM(D14:F14) -> -95 | H14: =+H13+T_T134[[#This Row],[Total]] -> 0 | I14: =IF(T_T134[[#This Row],[Total]]<0,T_T134[[#This Row],[Total]]*-1,0) -> 95
A15: 45747 | B15: Mantenimiento marzo/2025 | D15: 107 | E15: 5 | G15: =SUM(D15:F15) -> 112 | H15: =+H14+T_T134[[#This Row],[Total]] -> 112 | I15: =IF(T_T134[[#This Row],[Total]]<0,T_T134[[#This Row],[Total]]*-1,0) -> 0
B16: Pago matenimiento marzo/2025 | C16: 8892-8893 | D16: =-77-30 -> -107 | E16: -5 | G16: =SUM(D16:F16) -> -112 | H16: =+H15+T_T134[[#This Row],[Total]] -> 0 | I16: =IF(T_T134[[#This Row],[Total]]<0,T_T134[[#This Row],[Total]]*-1,0) -> 112
A17: 45777 | B17: Mantenimiento abril/2025 | D17: 107 | E17: 10 | G17: =SUM(D17:F17) -> 117 | H17: =+H16+T_T134[[#This Row],[Total]] -> 117 | I17: =IF(T_T134[[#This Row],[Total]]<0,T_T134[[#This Row],[Total]]*-1,0) -> 0
B18: Pago mantenimiento abril/2025 | C18: 8893-8895 | D18: =-30-77 -> -107 | E18: -10 | G18: =SUM(D18:F18) -> -117 | H18: =+H17+T_T134[[#This Row],[Total]] -> 0 | I18: =IF(T_T134[[#This Row],[Total]]<0,T_T134[[#This Row],[Total]]*-1,0) -> 117
A19: 45807 | B19: Mantenimiento mayo/2025 | D19: 107 | E19: 10 | G19: =SUM(D19:F19) -> 117 | H19: =+H18+T_T134[[#This Row],[Total]] -> 117 | I19: =IF(T_T134[[#This Row],[Total]]<0,T_T134[[#This Row],[Total]]*-1,0) -> 0
B20: Pago mantenimiento mayo/2025 | G20: =SUM(D20:F20) -> 0 | H20: =+H19+T_T134[[#This Row],[Total]] -> 117 | I20: =IF(T_T134[[#This Row],[Total]]<0,T_T134[[#This Row],[Total]]*-1,0) -> 0
A21: 45838 | B21: Mantenimiento junio/2025 | G21: =SUM(D21:F21) -> 0 | H21: =+H20+T_T134[[#This Row],[Total]] -> 117 | I21: =IF(T_T134[[#This Row],[Total]]<0,T_T134[[#This Row],[Total]]*-1,0) -> 0
B22: Pago mantenimiento junio/2025 | G22: =SUM(D22:F22) -> 0 | H22: =+H21+T_T134[[#This Row],[Total]] -> 117 | I22: =IF(T_T134[[#This Row],[Total]]<0,T_T134[[#This Row],[Total]]*-1,0) -> 0
A23: 45868 | B23: Mantenimiento julio/2025 | G23: =SUM(D23:F23) -> 0 | H23: =+H22+T_T134[[#This Row],[Total]] -> 117 | I23: =IF(T_T134[[#This Row],[Total]]<0,T_T134[[#This Row],[Total]]*-1,0) -> 0
B24: Pago mantenimient julio/2025 | G24: =SUM(D24:F24) -> 0 | H24: =+H23+T_T134[[#This Row],[Total]] -> 117 | I24: =IF(T_T134[[#This Row],[Total]]<0,T_T134[[#This Row],[Total]]*-1,0) -> 0
A25: 45899 | B25: Mantenimiento agosto/2025 | G25: =SUM(D25:F25) -> 0 | H25: =H24+G25 -> 117 | I25: =IF(T_T134[[#This Row],[Total]]<0,T_T134[[#This Row],[Total]]*-1,0) -> 0
B26: Pago mantenimiento agosto/2025 | G26: =SUM(D26:F26) -> 0 | H26: =H25+G26 -> 117 | I26: =IF(T_T134[[#This Row],[Total]]<0,T_T134[[#This Row],[Total]]*-1,0) -> 0
A27: 45930 | B27: Mantenimiento septiembre/2025 | G27: =SUM(D27:F27) -> 0 | H27: =H26+G27 -> 117 | I27: =IF(T_T134[[#This Row],[Total]]<0,T_T134[[#This Row],[Total]]*-1,0) -> 0
B28: Pago mantenimiento septiembre/2025 | G28: =SUM(D28:F28) -> 0 | H28: =H27+G28 -> 117 | I28: =IF(T_T134[[#This Row],[Total]]<0,T_T134[[#This Row],[Total]]*-1,0) -> 0
A29: 45960 | B29: Mantenimiento octubre /2025 | G29: =SUM(D29:F29) -> 0 | H29: =H28+G29 -> 117 | I29: =IF(T_T134[[#This Row],[Total]]<0,T_T134[[#This Row],[Total]]*-1,0) -> 0
B30: Pago mantenimiento octubre/2025 | G30: =SUM(D30:F30) -> 0 | H30: =H29+G30 -> 117 | I30: =IF(T_T134[[#This Row],[Total]]<0,T_T134[[#This Row],[Total]]*-1,0) -> 0
A31: 45991 | B31: Mantenimiento noviembre/2025 | G31: =SUM(D31:F31) -> 0 | H31: =H30+G31 -> 117 | I31: =IF(T_T134[[#This Row],[Total]]<0,T_T134[[#This Row],[Total]]*-1,0) -> 0
B32: Pago mantenimiento noviembre/2025 | G32: =SUM(D32:F32) -> 0 | H32: =H31+G32 -> 117 | I32: =IF(T_T134[[#This Row],[Total]]<0,T_T134[[#This Row],[Total]]*-1,0) -> 0
A33: 46021 | B33: Mantenimiento diciembre/2025 | G33: =SUM(D33:F33) -> 0 | H33: =H32+G33 -> 117 | I33: =IF(T_T134[[#This Row],[Total]]<0,T_T134[[#This Row],[Total]]*-1,0) -> 0
B34: Pago de Mantenimiento diciembre/2025 | G34: =SUM(D34:F34) -> 0 | H34: =H33+G34 -> 117 | I34: =IF(T_T134[[#This Row],[Total]]<0,T_T134[[#This Row],[Total]]*-1,0) -> 0
G35: =SUM(D35:F42) -> 0 | H35: =H34+G35 -> 117 | I35: =IF(T_T134[[#This Row],[Total]]<0,T_T134[[#This Row],[Total]]*-1,0) -> 0
G36: =SUM(D36:F43) -> 0 | H36: =H35+G36 -> 117 | I36: =IF(T_T134[[#This Row],[Total]]<0,T_T134[[#This Row],[Total]]*-1,0) -> 0
G37: =SUM(D37:F44) -> 0 | H37: =H36+G37 -> 117 | I37: =IF(T_T134[[#This Row],[Total]]<0,T_T134[[#This Row],[Total]]*-1,0) -> 0
G38: =SUM(D38:F45) -> 0 | H38: =H37+G38 -> 117 | I38: =IF(T_T134[[#This Row],[Total]]<0,T_T134[[#This Row],[Total]]*-1,0) -> 0
G39: =SUM(D39:F45) -> 0 | H39: =H38+G39 -> 117 | I39: =IF(T_T134[[#This Row],[Total]]<0,T_T134[[#This Row],[Total]]*-1,0) -> 0
G40: =SUM(D40:F45) -> 0 | H40: =H39+G40 -> 117 | I40: =IF(T_T134[[#This Row],[Total]]<0,T_T134[[#This Row],[Total]]*-1,0) -> 0
G41: =SUM(D41:F45) -> 0 | H41: =H40+G41 -> 117 | I41: =IF(T_T134[[#This Row],[Total]]<0,T_T134[[#This Row],[Total]]*-1,0) -> 0
...

Sheet LOCAL 02
A2: Departamento : | B2: LOCAL 02
A3: Propietario : | B3: SR. JOSE ORGAZ
A4: Inquilino : | B4: =LOOKUP(B2,#REF!,#REF!) -> #REF!
A5: Teléfono : | B5: =LOOKUP(B2,#REF!,#REF!) -> #REF!
A6: Celular : | B6: =LOOKUP(B2,#REF!,#REF!) -> #REF!
A7: Inquilino : | H7: Resumen
A9: Fecha | B9: Concepto | C9: Recibo | D9: Expensas | E9: Agua | F9: Multa | G9: Total | H9: Deuda | I9: Pagado
A11: 46052 | B11: Mantenimiento enero/2026 | D11: 70 | E11: 13 | G11: =SUM(D11:F11) -> 83 | H11: =+H10+T_T134144[[#This Row],[Total]] -> 83 | I11: =IF(T_T134144[[#This Row],[Total]]<0,T_T134144[[#This Row],[Total]]*-1,0) -> 0 | O11: 240
B12: Pago mantenimiento enero/2026 | G12: =SUM(D12:F12) -> 0 | H12: =+H11+T_T134144[[#This Row],[Total]] -> 83 | I12: =IF(T_T134144[[#This Row],[Total]]<0,T_T134144[[#This Row],[Total]]*-1,0) -> 0 | O12: 324
A13: 45715 | B13: Mantenimiento febrero/2026 | D13: 70 | E13: 13 | G13: =SUM(D13:F13) -> 83 | H13: =H12+G13 -> 166 | I13: =IF(T_T134144[[#This Row],[Total]]<0,T_T134144[[#This Row],[Total]]*-1,0) -> 0 | O13: =SUM(O11:O12) -> 564
B14: Pago mantenimiento febrero/2025 | G14: =SUM(D14:F14) -> 0 | H14: =H13+G14 -> 166 | I14: =IF(T_T134144[[#This Row],[Total]]<0,T_T134144[[#This Row],[Total]]*-1,0) -> 0
A15: 45747 | B15: Mantenimiento marzo/2025 | D15: 84 | E15: 13 | G15: =SUM(D15:F15) -> 97 | H15: =H14+G15 -> 263 | I15: =IF(T_T134144[[#This Row],[Total]]<0,T_T134144[[#This Row],[Total]]*-1,0) -> 0
B16: Pago matenimiento marzo/2025 | G16: =SUM(D16:F16) -> 0 | H16: =H15+G16 -> 263 | I16: =IF(T_T134144[[#This Row],[Total]]<0,T_T134144[[#This Row],[Total]]*-1,0) -> 0
A17: 45777 | B17: Mantenimiento abril/2025 | D17: 84 | E17: 13 | G17: =SUM(D17:F17) -> 97 | H17: =H16+G17 -> 360 | I17: =IF(T_T134144[[#This Row],[Total]]<0,T_T134144[[#This Row],[Total]]*-1,0) -> 0
B18: Pago mantenimiento abril/2025 | G18: =SUM(D18:F18) -> 0 | H18: =H17+G18 -> 360 | I18: =IF(T_T134144[[#This Row],[Total]]<0,T_T134144[[#This Row],[Total]]*-1,0) -> 0
A19: 45807 | B19: Mantenimiento mayo/2025 | D19: 84 | E19: 13 | G19: =SUM(D19:F19) -> 97 | H19: =H18+G19 -> 457 | I19: =IF(T_T134144[[#This Row],[Total]]<0,T_T134144[[#This Row],[Total]]*-1,0) -> 0
B20: Pago mantenimiento mayo/2025 | G20: =SUM(D20:F20) -> 0 | H20: =H19+G20 -> 457 | I20: =IF(T_T134144[[#This Row],[Total]]<0,T_T134144[[#This Row],[Total]]*-1,0) -> 0
A21: 45838 | B21: Mantenimiento junio/2025 | G21: =SUM(D21:F21) -> 0 | H21: =H20+G21 -> 457 | I21: =IF(T_T134144[[#This Row],[Total]]<0,T_T134144[[#This Row],[Total]]*-1,0) -> 0
B22: Pago mantenimiento junio/2025 | G22: =SUM(D22:F22) -> 0 | H22: =H21+G22 -> 457 | I22: =IF(T_T134144[[#This Row],[Total]]<0,T_T134144[[#This Row],[Total]]*-1,0) -> 0
A23: 45868 | B23: Mantenimiento julio/2025 | G23: =SUM(D23:F23) -> 0 | H23: =H22+G23 -> 457 | I23: =IF(T_T134144[[#This Row],[Total]]<0,T_T134144[[#This Row],[Total]]*-1,0) -> 0
B24: Pago mantenimient julio/2025 | G24: =SUM(D24:F24) -> 0 | H24: =H23+G24 -> 457 | I24: =IF(T_T134144[[#This Row],[Total]]<0,T_T134144[[#This Row],[Total]]*-1,0) -> 0
A25: 45899 | B25: Mantenimiento agosto/2025 | G25: =SUM(D25:F25) -> 0 | H25: =H24+G25 -> 457 | I25: =IF(T_T134144[[#This Row],[Total]]<0,T_T134144[[#This Row],[Total]]*-1,0) -> 0
B26: Pago mantenimiento agosto/2025 | G26: =SUM(D26:F26) -> 0 | H26: =H25+G26 -> 457 | I26: =IF(T_T134144[[#This Row],[Total]]<0,T_T134144[[#This Row],[Total]]*-1,0) -> 0
A27: 45930 | B27: Mantenimiento septiembre/2025 | G27: =SUM(D27:F27) -> 0 | H27: =H26+G27 -> 457 | I27: =IF(T_T134144[[#This Row],[Total]]<0,T_T134144[[#This Row],[Total]]*-1,0) -> 0
B28: Pago mantenimiento septiembre/2025 | G28: =SUM(D28:F28) -> 0 | H28: =H27+G28 -> 457 | I28: =IF(T_T134144[[#This Row],[Total]]<0,T_T134144[[#This Row],[Total]]*-1,0) -> 0
A29: 45960 | B29: Mantenimiento octubre /2025 | G29: =SUM(D29:F29) -> 0 | H29: =H28+G29 -> 457 | I29: =IF(T_T134144[[#This Row],[Total]]<0,T_T134144[[#This Row],[Total]]*-1,0) -> 0
B30: Pago mantenimiento octubre/2025 | G30: =SUM(D30:F30) -> 0 | H30: =H29+G30 -> 457 | I30: =IF(T_T134144[[#This Row],[Total]]<0,T_T134144[[#This Row],[Total]]*-1,0) -> 0
A31: 45991 | B31: Mantenimiento noviembre/2025 | G31: =SUM(D31:F31) -> 0 | H31: =H30+G31 -> 457 | I31: =IF(T_T134144[[#This Row],[Total]]<0,T_T134144[[#This Row],[Total]]*-1,0) -> 0
B32: Pago mantenimiento noviembre/2025 | G32: =SUM(D32:F32) -> 0 | H32: =H31+G32 -> 457 | I32: =IF(T_T134144[[#This Row],[Total]]<0,T_T134144[[#This Row],[Total]]*-1,0) -> 0
A33: 46021 | B33: Mantenimiento diciembre/2025 | G33: =SUM(D33:F33) -> 0 | H33: =H32+G33 -> 457 | I33: =IF(T_T134144[[#This Row],[Total]]<0,T_T134144[[#This Row],[Total]]*-1,0) -> 0
B34: Pago de Mantenimiento diciembre/2025 | G34: =SUM(D34:F34) -> 0 | H34: =H33+G34 -> 457 | I34: =IF(T_T134144[[#This Row],[Total]]<0,T_T134144[[#This Row],[Total]]*-1,0) -> 0
G35: =SUM(D35:F42) -> 0 | H35: =H34+G35 -> 457 | I35: =IF(T_T134144[[#This Row],[Total]]<0,T_T134144[[#This Row],[Total]]*-1,0) -> 0
G36: =SUM(D36:F43) -> 0 | H36: =H35+G36 -> 457 | I36: =IF(T_T134144[[#This Row],[Total]]<0,T_T134144[[#This Row],[Total]]*-1,0) -> 0
G37: =SUM(D37:F37) -> 0 | H37: =H36+G37 -> 457 | I37: =IF(T_T134144[[#This Row],[Total]]<0,T_T134144[[#This Row],[Total]]*-1,0) -> 0
G38: =SUM(D38:F38) -> 0 | H38: =H37+G38 -> 457 | I38: =IF(T_T134144[[#This Row],[Total]]<0,T_T134144[[#This Row],[Total]]*-1,0) -> 0
G39: =SUM(D39:F39) -> 0 | H39: =H38+G39 -> 457 | I39: =IF(T_T134144[[#This Row],[Total]]<0,T_T134144[[#This Row],[Total]]*-1,0) -> 0
G40: =SUM(D40:F40) -> 0 | H40: =H39+G40 -> 457 | I40: =IF(T_T134144[[#This Row],[Total]]<0,T_T134144[[#This Row],[Total]]*-1,0) -> 0
G41: =SUM(D41:F41) -> 0 | H41: =H40+G41 -> 457 | I41: =IF(T_T134144[[#This Row],[Total]]<0,T_T134144[[#This Row],[Total]]*-1,0) -> 0

Sheet LOCAL 03
A2: Departamento : | B2: LOCAL 03
A3: Propietario : | B3: MERY FERNANDEZ
A4: Inquilino : | B4: =LOOKUP(B2,#REF!,#REF!) -> #REF!
A5: Teléfono : | B5: =LOOKUP(B2,#REF!,#REF!) -> #REF!
A6: Celular : | B6: =LOOKUP(B2,#REF!,#REF!) -> #REF!
A7: Inquilino : | B7: SIMCORT LTDA | H7: Resumen
A9: Fecha | B9: Concepto | C9: Recibo | D9: Expensas | E9: Agua | F9: Multa | G9: Total | H9: Deuda | I9: Pagado | J9: Columna1 | K9: Columna2 | L9: Columna3
B10: DEUDA GESTION 2017-2020 | H10: 0
B11: DEUDA GESTION 2021 | H11: 0 | I11: =IF(T_T134145[[#This Row],[Total]]<0,T_T134145[[#This Row],[Total]]*-1,0) -> 0
B12: DEUDA GESTION 2022 | H12: 0 | I12: =IF(T_T134145[[#This Row],[Total]]<0,T_T134145[[#This Row],[Total]]*-1,0) -> 0
B13: DEUDA GESTION 2023 | H13: 0 | I13: =IF(T_T134145[[#This Row],[Total]]<0,T_T134145[[#This Row],[Total]]*-1,0) -> 0
B14: DEUDA GESTION 2024 | I14: =IF(T_T134145[[#This Row],[Total]]<0,T_T134145[[#This Row],[Total]]*-1,0) -> 0
A15: 46052 | B15: Mantenimiento enero/2026 | D15: 102 | E15: 15 | G15: =SUM(D15:F15) -> 117 | H15: =+H13+T_T134145[[#This Row],[Total]] -> 117 | I15: =IF(T_T134145[[#This Row],[Total]]<0,T_T134145[[#This Row],[Total]]*-1,0) -> 0
B16: Pago mantenimiento enero/2026 | C16: 8645 | D16: -102 | E16: -15 | G16: =SUM(D16:F16) -> -117 | H16: =H15+G16 -> 0 | I16: =IF(T_T134145[[#This Row],[Total]]<0,T_T134145[[#This Row],[Total]]*-1,0) -> 117
A17: 45715 | B17: Mantenimiento febrero/2025 | D17: 102 | E17: 13 | G17: =SUM(D17:F17) -> 115 | H17: =H16+G17 -> 115 | I17: =IF(T_T134145[[#This Row],[Total]]<0,T_T134145[[#This Row],[Total]]*-1,0) -> 0
B18: Pago mantenimiento febrero/2025 | G18: =SUM(D18:F18) -> 0 | H18: =H17+G18 -> 115 | I18: =IF(T_T134145[[#This Row],[Total]]<0,T_T134145[[#This Row],[Total]]*-1,0) -> 0
A19: 45747 | B19: Mantenimiento marzo/2025 | D19: 122 | E19: 9 | G19: =SUM(D19:F19) -> 131 | H19: =H18+G19 -> 246 | I19: =IF(T_T134145[[#This Row],[Total]]<0,T_T134145[[#This Row],[Total]]*-1,0) -> 0
B20: Pago matenimiento marzo/2025 | G20: =SUM(D20:F20) -> 0 | H20: =H19+G20 -> 246 | I20: =IF(T_T134145[[#This Row],[Total]]<0,T_T134145[[#This Row],[Total]]*-1,0) -> 0
A21: 45777 | B21: Mantenimiento abril/2025 | D21: 122 | E21: 1 | G21: =SUM(D21:F21) -> 123 | H21: =H20+G21 -> 369 | I21: =IF(T_T134145[[#This Row],[Total]]<0,T_T134145[[#This Row],[Total]]*-1,0) -> 0
B22: Pago mantenimiento abril/2025 | G22: =SUM(D22:F22) -> 0 | H22: =H21+G22 -> 369 | I22: =IF(T_T134145[[#This Row],[Total]]<0,T_T134145[[#This Row],[Total]]*-1,0) -> 0
A23: 45807 | B23: Mantenimiento mayo/2025 | D23: 122 | E23: 8 | G23: =SUM(D23:F23) -> 130 | H23: =H22+G23 -> 499 | I23: =IF(T_T134145[[#This Row],[Total]]<0,T_T134145[[#This Row],[Total]]*-1,0) -> 0
B24: Pago mantenimiento mayo/2025 | G24: =SUM(D24:F24) -> 0 | H24: =H23+G24 -> 499 | I24: =IF(T_T134145[[#This Row],[Total]]<0,T_T134145[[#This Row],[Total]]*-1,0) -> 0
A25: 45838 | B25: Mantenimiento junio/2025 | G25: =SUM(D25:F25) -> 0 | H25: =H24+G25 -> 499 | I25: =IF(T_T134145[[#This Row],[Total]]<0,T_T134145[[#This Row],[Total]]*-1,0) -> 0
B26: Pago mantenimiento junio/2025 | G26: =SUM(D26:F26) -> 0 | H26: =H25+G26 -> 499 | I26: =IF(T_T134145[[#This Row],[Total]]<0,T_T134145[[#This Row],[Total]]*-1,0) -> 0
A27: 45868 | B27: Mantenimiento julio/2025 | G27: =SUM(D27:F27) -> 0 | H27: =H26+G27 -> 499 | I27: =IF(T_T134145[[#This Row],[Total]]<0,T_T134145[[#This Row],[Total]]*-1,0) -> 0
B28: Pago mantenimient julio/2025 | G28: =SUM(D28:F28) -> 0 | H28: =H27+G28 -> 499 | I28: =IF(T_T134145[[#This Row],[Total]]<0,T_T134145[[#This Row],[Total]]*-1,0) -> 0
A29: 45899 | B29: Mantenimiento agosto/2025 | G29: =SUM(D29:F29) -> 0 | H29: =H28+G29 -> 499 | I29: =IF(T_T134145[[#This Row],[Total]]<0,T_T134145[[#This Row],[Total]]*-1,0) -> 0
B30: Pago mantenimiento agosto/2025 | G30: =SUM(D30:F30) -> 0 | H30: =H29+G30 -> 499 | I30: =IF(T_T134145[[#This Row],[Total]]<0,T_T134145[[#This Row],[Total]]*-1,0) -> 0
A31: 45930 | B31: Mantenimiento septiembre/2025 | G31: =SUM(D31:F31) -> 0 | H31: =H30+G31 -> 499 | I31: =IF(T_T134145[[#This Row],[Total]]<0,T_T134145[[#This Row],[Total]]*-1,0) -> 0
B32: Pago mantenimiento septiembre/2025 | G32: =SUM(D32:F32) -> 0 | H32: =H31+G32 -> 499 | I32: =IF(T_T134145[[#This Row],[Total]]<0,T_T134145[[#This Row],[Total]]*-1,0) -> 0
A33: 45960 | B33: Mantenimiento octubre /2025 | G33: =SUM(D33:F33) -> 0 | H33: =H32+G33 -> 499 | I33: =IF(T_T134145[[#This Row],[Total]]<0,T_T134145[[#This Row],[Total]]*-1,0) -> 0
B34: Pago mantenimiento octubre/2025 | G34: =SUM(D34:F34) -> 0 | H34: =H33+G34 -> 499 | I34: =IF(T_T134145[[#This Row],[Total]]<0,T_T134145[[#This Row],[Total]]*-1,0) -> 0
A35: 45991 | B35: Mantenimiento noviembre/2025 | G35: =SUM(D35:F35) -> 0 | H35: =H34+G35 -> 499 | I35: =IF(T_T134145[[#This Row],[Total]]<0,T_T134145[[#This Row],[Total]]*-1,0) -> 0
B36: Pago mantenimiento noviembre/2025 | G36: =SUM(D36:F36) -> 0 | H36: =H35+G36 -> 499 | I36: =IF(T_T134145[[#This Row],[Total]]<0,T_T134145[[#This Row],[Total]]*-1,0) -> 0
A37: 46021 | B37: Mantenimiento diciembre/2025 | G37: =SUM(D37:F37) -> 0 | H37: =H36+G37 -> 499 | I37: =IF(T_T134145[[#This Row],[Total]]<0,T_T134145[[#This Row],[Total]]*-1,0) -> 0
B38: Pago de Mantenimiento diciembre/2025 | G38: =SUM(D38:F38) -> 0 | H38: =H37+G38 -> 499 | I38: =IF(T_T134145[[#This Row],[Total]]<0,T_T134145[[#This Row],[Total]]*-1,0) -> 0
G39: =SUM(D39:F46) -> 0 | H39: =H38+G39 -> 499 | I39: =IF(T_T134145[[#This Row],[Total]]<0,T_T134145[[#This Row],[Total]]*-1,0) -> 0
G40: =SUM(D40:F47) -> 0 | H40: =H39+G40 -> 499 | I40: =IF(T_T134145[[#This Row],[Total]]<0,T_T134145[[#This Row],[Total]]*-1,0) -> 0

Sheet LOCAL 04
A2: Departamento : | B2: LOCAL 04
A3: Propietario : | B3: PAULA BURGOS
A4: Inquilino : | B4: =LOOKUP(B2,#REF!,#REF!) -> #REF!
A5: Teléfono : | B5: =LOOKUP(B2,#REF!,#REF!) -> #REF!
A6: Celular : | B6: =LOOKUP(B2,#REF!,#REF!) -> #REF!
A7: Correo : | B7: =LOOKUP(B2,#REF!,#REF!) -> #REF! | H7: Resumen
A9: Fecha | B9: Concepto | C9: Recibo | D9: Expensas | E9: Agua | F9: Multa | G9: Total | H9: Deuda | I9: Pagado | J9: Columna1 | K9: Columna2 | L9: Columna3
B10: DEUDA GESTION 2017-2020 | H10: 0 | I10: =IF(T_T1343[[#This Row],[Total]]<0,T_T1343[[#This Row],[Total]]*-1,0) -> 0
B11: DEUDA GESTION 2021 | H11: 0 | I11: =IF(T_T1343[[#This Row],[Total]]<0,T_T1343[[#This Row],[Total]]*-1,0) -> 0
B12: DEUDA GESTION 2022 | H12: 0 | I12: =IF(T_T1343[[#This Row],[Total]]<0,T_T1343[[#This Row],[Total]]*-1,0) -> 0
B13: DEUDA GESTION 2023 | H13: 0 | I13: =IF(T_T1343[[#This Row],[Total]]<0,T_T1343[[#This Row],[Total]]*-1,0) -> 0
B14: DEUDA GESTION 2024 | I14: =IF(T_T1343[[#This Row],[Total]]<0,T_T1343[[#This Row],[Total]]*-1,0) -> 0
A15: 46052 | B15: Mantenimiento enero/2026 | D15: 101 | E15: 104 | G15: =SUM(D15:F15) -> 205 | H15: =+H13+T_T1343[[#This Row],[Total]] -> 205 | I15: =IF(T_T1343[[#This Row],[Total]]<0,T_T1343[[#This Row],[Total]]*-1,0) -> 0
B16: Pago mantenimiento enero/2026 | G16: =SUM(D16:F16) -> 0 | H16: =H15+G16 -> 205 | I16: =IF(T_T1343[[#This Row],[Total]]<0,T_T1343[[#This Row],[Total]]*-1,0) -> 0
A17: 45715 | B17: Mantenimiento febrero/2026 | D17: 101 | E17: 259 | G17: =SUM(D17:F17) -> 360 | H17: =H16+G17 -> 565 | I17: =IF(T_T1343[[#This Row],[Total]]<0,T_T1343[[#This Row],[Total]]*-1,0) -> 0
B18: Pago mantenimiento febrero/2026 | G18: =SUM(D18:F18) -> 0 | H18: =H17+G18 -> 565 | I18: =IF(T_T1343[[#This Row],[Total]]<0,T_T1343[[#This Row],[Total]]*-1,0) -> 0
A19: 45747 | B19: Mantenimiento marzo/2025 | D19: 121 | E19: 30 | G19: =SUM(D19:F19) -> 151 | H19: =H18+G19 -> 716 | I19: =IF(T_T1343[[#This Row],[Total]]<0,T_T1343[[#This Row],[Total]]*-1,0) -> 0
B20: Pago matenimiento marzo/2025 | G20: =SUM(D20:F20) -> 0 | H20: =H19+G20 -> 716 | I20: =IF(T_T1343[[#This Row],[Total]]<0,T_T1343[[#This Row],[Total]]*-1,0) -> 0
A21: 45777 | B21: Mantenimiento abril/2025 | D21: 121 | E21: 3 | G21: =SUM(D21:F21) -> 124 | H21: =H20+G21 -> 840 | I21: =IF(T_T1343[[#This Row],[Total]]<0,T_T1343[[#This Row],[Total]]*-1,0) -> 0
B22: Pago mantenimiento abril/2025 | G22: =SUM(D22:F22) -> 0 | H22: =H21+G22 -> 840 | I22: =IF(T_T1343[[#This Row],[Total]]<0,T_T1343[[#This Row],[Total]]*-1,0) -> 0
A23: 45807 | B23: Mantenimiento mayo/2025 | D23: 121 | E23: 17 | G23: =SUM(D23:F23) -> 138 | H23: =H22+G23 -> 978 | I23: =IF(T_T1343[[#This Row],[Total]]<0,T_T1343[[#This Row],[Total]]*-1,0) -> 0
B24: Pago mantenimiento mayo/2025 | G24: =SUM(D24:F24) -> 0 | H24: =H23+G24 -> 978 | I24: =IF(T_T1343[[#This Row],[Total]]<0,T_T1343[[#This Row],[Total]]*-1,0) -> 0
A25: 45838 | B25: Mantenimiento junio/2025 | G25: =SUM(D25:F25) -> 0 | H25: =H24+G25 -> 978 | I25: =IF(T_T1343[[#This Row],[Total]]<0,T_T1343[[#This Row],[Total]]*-1,0) -> 0
B26: Pago mantenimiento junio/2025 | G26: =SUM(D26:F26) -> 0 | H26: =H25+G26 -> 978 | I26: =IF(T_T1343[[#This Row],[Total]]<0,T_T1343[[#This Row],[Total]]*-1,0) -> 0 | N26: SABRINA ARDAYA
A27: 45868 | B27: Mantenimiento julio/2025 | G27: =SUM(D27:F27) -> 0 | H27: =H26+G27 -> 978 | I27: =IF(T_T1343[[#This Row],[Total]]<0,T_T1343[[#This Row],[Total]]*-1,0) -> 0
B28: Pago mantenimient julio/2025 | G28: =SUM(D28:F28) -> 0 | H28: =H27+G28 -> 978 | I28: =IF(T_T1343[[#This Row],[Total]]<0,T_T1343[[#This Row],[Total]]*-1,0) -> 0
A29: 45899 | B29: Mantenimiento agosto/2025 | G29: =SUM(D29:F29) -> 0 | H29: =H28+G29 -> 978 | I29: =IF(T_T1343[[#This Row],[Total]]<0,T_T1343[[#This Row],[Total]]*-1,0) -> 0
B30: Pago mantenimiento agosto/2025 | G30: =SUM(D30:F30) -> 0 | H30: =H29+G30 -> 978 | I30: =IF(T_T1343[[#This Row],[Total]]<0,T_T1343[[#This Row],[Total]]*-1,0) -> 0
A31: 45930 | B31: Mantenimiento septiembre/2025 | G31: =SUM(D31:F31) -> 0 | H31: =H30+G31 -> 978 | I31: =IF(T_T1343[[#This Row],[Total]]<0,T_T1343[[#This Row],[Total]]*-1,0) -> 0
B32: Pago mantenimiento septiembre/2025 | G32: =SUM(D32:F32) -> 0 | H32: =H31+G32 -> 978 | I32: =IF(T_T1343[[#This Row],[Total]]<0,T_T1343[[#This Row],[Total]]*-1,0) -> 0
A33: 45960 | B33: Mantenimiento octubre /2025 | G33: =SUM(D33:F33) -> 0 | H33: =H32+G33 -> 978 | I33: =IF(T_T1343[[#This Row],[Total]]<0,T_T1343[[#This Row],[Total]]*-1,0) -> 0
B34: Pago mantenimiento octubre/2025 | G34: =SUM(D34:F34) -> 0 | H34: =H33+G34 -> 978 | I34: =IF(T_T1343[[#This Row],[Total]]<0,T_T1343[[#This Row],[Total]]*-1,0) -> 0
A35: 45991 | B35: Mantenimiento noviembre/2025 | G35: =SUM(D35:F35) -> 0 | H35: =H34+G35 -> 978 | I35: =IF(T_T1343[[#This Row],[Total]]<0,T_T1343[[#This Row],[Total]]*-1,0) -> 0
B36: Pago mantenimiento noviembre/2025 | G36: =SUM(D36:F36) -> 0 | H36: =H35+G36 -> 978 | I36: =IF(T_T1343[[#This Row],[Total]]<0,T_T1343[[#This Row],[Total]]*-1,0) -> 0
A37: 46021 | B37: Mantenimiento diciembre/2025 | G37: =SUM(D37:F37) -> 0 | H37: =H36+G37 -> 978 | I37: =IF(T_T1343[[#This Row],[Total]]<0,T_T1343[[#This Row],[Total]]*-1,0) -> 0
B38: Pago de Mantenimiento diciembre/2025 | G38: =SUM(D38:F38) -> 0 | H38: =H37+G38 -> 978 | I38: =IF(T_T1343[[#This Row],[Total]]<0,T_T1343[[#This Row],[Total]]*-1,0) -> 0
G39: =SUM(D39:F46) -> 0 | H39: =H38+G39 -> 978 | I39: =IF(T_T1343[[#This Row],[Total]]<0,T_T1343[[#This Row],[Total]]*-1,0) -> 0
G40: =SUM(D40:F47) -> 0 | H40: =H39+G40 -> 978 | I40: =IF(T_T1343[[#This Row],[Total]]<0,T_T1343[[#This Row],[Total]]*-1,0) -> 0

Sheet LOCAL 05
A2: Departamento : | B2: LOCAL 05
A3: Propietario : | B3: LUPE MARCELA LECOÑA
A4: Inquilino : | B4: =LOOKUP(B2,#REF!,#REF!) -> #REF!
A5: Teléfono : | B5: =LOOKUP(B2,#REF!,#REF!) -> #REF!
A6: Celular : | B6: =LOOKUP(B2,#REF!,#REF!) -> #REF!
A7: Correo : | B7: =LOOKUP(B2,#REF!,#REF!) -> #REF! | H7: Resumen
A8: INQULINO: | B8: RAUL QUIÑONES
A9: Fecha | B9: Concepto | C9: Recibo | D9: Expensas | E9: Agua | F9: Multa | G9: Total | H9: Deuda | I9: Pagado
B10: DEUDA GESTION 2017-2020 | H10: 0 | I10: =IF(T_T1345[[#This Row],[Total]]<0,T_T1345[[#This Row],[Total]]*-1,0) -> 0
B11: DEUDA GESTION 2021 | H11: =H10+G11 -> 0 | I11: =IF(T_T1345[[#This Row],[Total]]<0,T_T1345[[#This Row],[Total]]*-1,0) -> 0
B12: DEUDA GESTION 2022 | H12: =H11+G12 -> 0 | I12: =IF(T_T1345[[#This Row],[Total]]<0,T_T1345[[#This Row],[Total]]*-1,0) -> 0
B13: DEUDA GESTION 2023 | H13: =H11+G13 -> 0 | I13: =IF(T_T1345[[#This Row],[Total]]<0,T_T1345[[#This Row],[Total]]*-1,0) -> 0
B14: DEUDA GESTION 2024 | H14: =H13+G14 -> 0 | I14: =IF(T_T1345[[#This Row],[Total]]<0,T_T1345[[#This Row],[Total]]*-1,0) -> 0
A15: 46052 | B15: Mantenimiento enero/2026 | D15: 101 | E15: 13 | G15: =SUM(D15:F15) -> 114 | H15: =H13+G15 -> 114 | I15: =IF(T_T1345[[#This Row],[Total]]<0,T_T1345[[#This Row],[Total]]*-1,0) -> 0
B16: Pago mantenimiento enero/2026 | C16: 8555 | D16: -101 | E16: -13 | G16: =SUM(D16:F16) -> -114 | H16: =H15+G16 -> 0 | I16: =IF(T_T1345[[#This Row],[Total]]<0,T_T1345[[#This Row],[Total]]*-1,0) -> 114
A17: 45715 | B17: Mantenimiento febrero/2025 | D17: 101 | E17: 13 | G17: =SUM(D17:F17) -> 114 | H17: =H16+G17 -> 114 | I17: =IF(T_T1345[[#This Row],[Total]]<0,T_T1345[[#This Row],[Total]]*-1,0) -> 0
B18: Pago mantenimiento febrero/2025 | C18: 8736 | D18: -101 | E18: -13 | G18: =SUM(D18:F18) -> -114 | H18: =H17+G18 -> 0 | I18: =IF(T_T1345[[#This Row],[Total]]<0,T_T1345[[#This Row],[Total]]*-1,0) -> 114
A19: 45747 | B19: Mantenimiento marzo/2025 | D19: 121 | E19: 13 | G19: =SUM(D19:F19) -> 134 | H19: =H18+G19 -> 134 | I19: =IF(T_T1345[[#This Row],[Total]]<0,T_T1345[[#This Row],[Total]]*-1,0) -> 0
B20: Pago matenimiento marzo/2025 | C20: 8815 | D20: -121 | E20: -13 | G20: =SUM(D20:F20) -> -134 | H20: =H19+G20 -> 0 | I20: =IF(T_T1345[[#This Row],[Total]]<0,T_T1345[[#This Row],[Total]]*-1,0) -> 134
A21: 45777 | B21: Mantenimiento abril/2025 | D21: 121 | E21: 13 | G21: =SUM(D21:F21) -> 134 | H21: =H20+G21 -> 134 | I21: =IF(T_T1345[[#This Row],[Total]]<0,T_T1345[[#This Row],[Total]]*-1,0) -> 0
B22: Pago mantenimiento abril/2025 | C22: 8951 | D22: -121 | E22: -13 | G22: =SUM(D22:F22) -> -134 | H22: =H21+G22 -> 0 | I22: =IF(T_T1345[[#This Row],[Total]]<0,T_T1345[[#This Row],[Total]]*-1,0) -> 134
A23: 45807 | B23: Mantenimiento mayo/2025 | G23: =SUM(D23:F23) -> 0 | H23: =H22+G23 -> 0 | I23: =IF(T_T1345[[#This Row],[Total]]<0,T_T1345[[#This Row],[Total]]*-1,0) -> 0
B24: Pago mantenimiento mayo/2025 | G24: =SUM(D24:F24) -> 0 | H24: =H23+G24 -> 0 | I24: =IF(T_T1345[[#This Row],[Total]]<0,T_T1345[[#This Row],[Total]]*-1,0) -> 0
A25: 45838 | B25: Mantenimiento junio/2025 | G25: =SUM(D25:F25) -> 0 | H25: =H24+G25 -> 0 | I25: =IF(T_T1345[[#This Row],[Total]]<0,T_T1345[[#This Row],[Total]]*-1,0) -> 0
B26: Pago mantenimiento junio/2025 | G26: =SUM(D26:F26) -> 0 | H26: =H25+G26 -> 0 | I26: =IF(T_T1345[[#This Row],[Total]]<0,T_T1345[[#This Row],[Total]]*-1,0) -> 0
A27: 45868 | B27: Mantenimiento julio/2025 | G27: =SUM(D27:F27) -> 0 | H27: =H26+G27 -> 0 | I27: =IF(T_T1345[[#This Row],[Total]]<0,T_T1345[[#This Row],[Total]]*-1,0) -> 0
B28: Pago mantenimient julio/2025 | G28: =SUM(D28:F28) -> 0 | H28: =H27+G28 -> 0 | I28: =IF(T_T1345[[#This Row],[Total]]<0,T_T1345[[#This Row],[Total]]*-1,0) -> 0
A29: 45899 | B29: Mantenimiento agosto/2025 | G29: =SUM(D29:F29) -> 0 | H29: =H28+G29 -> 0 | I29: =IF(T_T1345[[#This Row],[Total]]<0,T_T1345[[#This Row],[Total]]*-1,0) -> 0
B30: Pago mantenimiento agosto/2025 | G30: =SUM(D30:F30) -> 0 | H30: =H29+G30 -> 0 | I30: =IF(T_T1345[[#This Row],[Total]]<0,T_T1345[[#This Row],[Total]]*-1,0) -> 0
A31: 45930 | B31: Mantenimiento septiembre/2025 | G31: =SUM(D31:F31) -> 0 | H31: =H30+G31 -> 0 | I31: =IF(T_T1345[[#This Row],[Total]]<0,T_T1345[[#This Row],[Total]]*-1,0) -> 0
B32: Pago mantenimiento septiembre/2025 | G32: =SUM(D32:F32) -> 0 | H32: =H31+G32 -> 0 | I32: =IF(T_T1345[[#This Row],[Total]]<0,T_T1345[[#This Row],[Total]]*-1,0) -> 0
A33: 45960 | B33: Mantenimiento octubre /2025 | G33: =SUM(D33:F33) -> 0 | H33: =H32+G33 -> 0 | I33: =IF(T_T1345[[#This Row],[Total]]<0,T_T1345[[#This Row],[Total]]*-1,0) -> 0
B34: Pago mantenimiento octubre/2025 | G34: =SUM(D34:F34) -> 0 | H34: =H33+G34 -> 0 | I34: =IF(T_T1345[[#This Row],[Total]]<0,T_T1345[[#This Row],[Total]]*-1,0) -> 0
A35: 45991 | B35: Mantenimiento noviembre/2025 | G35: =SUM(D35:F35) -> 0 | H35: =H34+G35 -> 0 | I35: =IF(T_T1345[[#This Row],[Total]]<0,T_T1345[[#This Row],[Total]]*-1,0) -> 0
B36: Pago mantenimiento noviembre/2025 | G36: =SUM(D36:F36) -> 0 | H36: =H35+G36 -> 0 | I36: =IF(T_T1345[[#This Row],[Total]]<0,T_T1345[[#This Row],[Total]]*-1,0) -> 0
A37: 46021 | B37: Mantenimiento diciembre/2025 | G37: =SUM(D37:F37) -> 0 | H37: =H36+G37 -> 0 | I37: =IF(T_T1345[[#This Row],[Total]]<0,T_T1345[[#This Row],[Total]]*-1,0) -> 0
B38: Pago de Mantenimiento diciembre/2025 | G38: =SUM(D38:F38) -> 0 | H38: =H37+G38 -> 0 | I38: =IF(T_T1345[[#This Row],[Total]]<0,T_T1345[[#This Row],[Total]]*-1,0) -> 0
G39: =SUM(D39:F46) -> 0 | H39: =H38+G39 -> 0 | I39: =IF(T_T1345[[#This Row],[Total]]<0,T_T1345[[#This Row],[Total]]*-1,0) -> 0
G40: =SUM(D40:F47) -> 0 | H40: =H39+G40 -> 0 | I40: =IF(T_T1345[[#This Row],[Total]]<0,T_T1345[[#This Row],[Total]]*-1,0) -> 0

Sheet LOCAL 06
A2: Departamento : | B2: LOCAL 06
A3: Propietario : | B3: =LOOKUP(B2,#REF!,#REF!) -> #REF!
A4: Inquilino : | B4: =LOOKUP(B2,#REF!,#REF!) -> #REF!
A5: Teléfono : | B5: =LOOKUP(B2,#REF!,#REF!) -> #REF!
A6: Celular : | B6: =LOOKUP(B2,#REF!,#REF!) -> #REF!
A7: Correo : | B7: LOURDEZ CONDORI
A8: INQUILINO VERONICA RODRIGUEZ
A9: Fecha | B9: Concepto | C9: Recibo | D9: Expensas | E9: Agua | F9: Multa | G9: Total | H9: Deuda | I9: Pagado | J9: Columna1 | K9: Columna2
B10: DEUDA GESTION 2017-2020 | H10: 0 | I10: =IF(T_T1346[[#This Row],[Total]]<0,T_T1346[[#This Row],[Total]]*-1,0) -> 0
B11: DEUDA GESTION 2021 | H11: 0 | I11: =IF(T_T1346[[#This Row],[Total]]<0,T_T1346[[#This Row],[Total]]*-1,0) -> 0
B12: DEUDA GESTION 2022 | H12: 0 | I12: =IF(T_T1346[[#This Row],[Total]]<0,T_T1346[[#This Row],[Total]]*-1,0) -> 0
B13: DEUDA GESTION 2023 | H13: 0 | I13: =IF(T_T1346[[#This Row],[Total]]<0,T_T1346[[#This Row],[Total]]*-1,0) -> 0
B14: DEUDA GESTION 2024 | I14: =IF(T_T1346[[#This Row],[Total]]<0,T_T1346[[#This Row],[Total]]*-1,0) -> 0
A15: 46052 | B15: Mantenimiento enero/2026 | D15: 134 | E15: 5 | G15: =SUM(D15:F15) -> 139 | H15: =+H13+T_T1346[[#This Row],[Total]] -> 139 | I15: =IF(T_T1346[[#This Row],[Total]]<0,T_T1346[[#This Row],[Total]]*-1,0) -> 0
B16: Pago mantenimiento enero/2026 | C16: 8544- 8603 | D16: =-108-26 -> -134 | E16: -5 | G16: =SUM(D16:F16) -> -139 | H16: =H15+G16 -> 0 | I16: =IF(T_T1346[[#This Row],[Total]]<0,T_T1346[[#This Row],[Total]]*-1,0) -> 139 | K16: parqueo nfr
A17: 45715 | B17: Mantenimiento febrero/2025 | D17: 134 | E17: 18 | G17: =SUM(D17:F17) -> 152 | H17: =H16+G17 -> 152 | I17: =IF(T_T1346[[#This Row],[Total]]<0,T_T1346[[#This Row],[Total]]*-1,0) -> 0
B18: Pago mantenimiento febrero/2025 | C18: 8665-8699 | D18: =-108-26 -> -134 | E18: -18 | G18: =SUM(D18:F18) -> -152 | H18: =H17+G18 -> 0 | I18: =IF(T_T1346[[#This Row],[Total]]<0,T_T1346[[#This Row],[Total]]*-1,0) -> 152
A19: 45747 | B19: Mantenimiento marzo/2025 | D19: =129+30 -> 159 | E19: 45 | G19: =SUM(D19:F19) -> 204 | H19: =H18+G19 -> 204 | I19: =IF(T_T1346[[#This Row],[Total]]<0,T_T1346[[#This Row],[Total]]*-1,0) -> 0
B20: Pago matenimiento marzo/2025 | C20: 8797-8812 | D20: =-30-129 -> -159 | E20: -45 | G20: =SUM(D20:F20) -> -204 | H20: =H19+G20 -> 0 | I20: =IF(T_T1346[[#This Row],[Total]]<0,T_T1346[[#This Row],[Total]]*-1,0) -> 204
A21: 45777 | B21: Mantenimiento abril/2025 | D21: =129+30 -> 159 | E21: 70 | G21: =SUM(D21:F21) -> 229 | H21: =H20+G21 -> 229 | I21: =IF(T_T1346[[#This Row],[Total]]<0,T_T1346[[#This Row],[Total]]*-1,0) -> 0
B22: Pago mantenimiento abril/2025 | C22: 8928-8931 | D22: =-30-129 -> -159 | E22: -70 | G22: =SUM(D22:F22) -> -229 | H22: =H21+G22 -> 0 | I22: =IF(T_T1346[[#This Row],[Total]]<0,T_T1346[[#This Row],[Total]]*-1,0) -> 229
A23: 45807 | B23: Mantenimiento mayo/2025 | D23: 159 | E23: 72 | G23: =SUM(D23:F23) -> 231 | H23: =H22+G23 -> 231 | I23: =IF(T_T1346[[#This Row],[Total]]<0,T_T1346[[#This Row],[Total]]*-1,0) -> 0
B24: Pago mantenimiento mayo/2025 | G24: =SUM(D24:F24) -> 0 | H24: =H23+G24 -> 231 | I24: =IF(T_T1346[[#This Row],[Total]]<0,T_T1346[[#This Row],[Total]]*-1,0) -> 0
A25: 45838 | B25: Mantenimiento junio/2025 | G25: =SUM(D25:F25) -> 0 | H25: =H24+G25 -> 231 | I25: =IF(T_T1346[[#This Row],[Total]]<0,T_T1346[[#This Row],[Total]]*-1,0) -> 0
B26: Pago mantenimiento junio/2025 | G26: =SUM(D26:F26) -> 0 | H26: =H25+G26 -> 231 | I26: =IF(T_T1346[[#This Row],[Total]]<0,T_T1346[[#This Row],[Total]]*-1,0) -> 0 | L26: nuevo inquilino desde julio
A27: 45868 | B27: Mantenimiento julio/2025 | G27: =SUM(D27:F27) -> 0 | H27: =H26+G27 -> 231 | I27: =IF(T_T1346[[#This Row],[Total]]<0,T_T1346[[#This Row],[Total]]*-1,0) -> 0 | L27: DORIS SAAVEDRA
B28: Pago mantenimient julio/2025 | G28: =SUM(D28:F28) -> 0 | H28: =H27+G28 -> 231 | I28: =IF(T_T1346[[#This Row],[Total]]<0,T_T1346[[#This Row],[Total]]*-1,0) -> 0
A29: 45899 | B29: Mantenimiento agosto/2025 | G29: =SUM(D29:F29) -> 0 | H29: =H28+G29 -> 231 | I29: =IF(T_T1346[[#This Row],[Total]]<0,T_T1346[[#This Row],[Total]]*-1,0) -> 0
B30: Pago mantenimiento agosto/2025 | G30: =SUM(D30:F30) -> 0 | H30: =H29+G30 -> 231 | I30: =IF(T_T1346[[#This Row],[Total]]<0,T_T1346[[#This Row],[Total]]*-1,0) -> 0
A31: 45930 | B31: Mantenimiento septiembre/2025 | G31: =SUM(D31:F31) -> 0 | H31: =H30+G31 -> 231 | I31: =IF(T_T1346[[#This Row],[Total]]<0,T_T1346[[#This Row],[Total]]*-1,0) -> 0
B32: Pago mantenimiento septiembre/2025 | G32: =SUM(D32:F32) -> 0 | H32: =H31+G32 -> 231 | I32: =IF(T_T1346[[#This Row],[Total]]<0,T_T1346[[#This Row],[Total]]*-1,0) -> 0
A33: 45960 | B33: Mantenimiento octubre /2025 | G33: =SUM(D33:F33) -> 0 | H33: =H32+G33 -> 231 | I33: =IF(T_T1346[[#This Row],[Total]]<0,T_T1346[[#This Row],[Total]]*-1,0) -> 0
B34: Pago mantenimiento octubre/2025 | G34: =SUM(D34:F34) -> 0 | H34: =H33+G34 -> 231 | I34: =IF(T_T1346[[#This Row],[Total]]<0,T_T1346[[#This Row],[Total]]*-1,0) -> 0
A35: 45991 | B35: Mantenimiento noviembre/2025 | G35: =SUM(D35:F35) -> 0 | H35: =H34+G35 -> 231 | I35: =IF(T_T1346[[#This Row],[Total]]<0,T_T1346[[#This Row],[Total]]*-1,0) -> 0
B36: Pago mantenimiento noviembre/2025 | G36: =SUM(D36:F36) -> 0 | H36: =H35+G36 -> 231 | I36: =IF(T_T1346[[#This Row],[Total]]<0,T_T1346[[#This Row],[Total]]*-1,0) -> 0
A37: 46021 | B37: Mantenimiento diciembre/2025 | G37: =SUM(D37:F37) -> 0 | H37: =H36+G37 -> 231 | I37: =IF(T_T1346[[#This Row],[Total]]<0,T_T1346[[#This Row],[Total]]*-1,0) -> 0
B38: Pago de Mantenimiento diciembre/2025 | G38: =SUM(D38:F38) -> 0 | H38: =H37+G38 -> 231 | I38: =IF(T_T1346[[#This Row],[Total]]<0,T_T1346[[#This Row],[Total]]*-1,0) -> 0
G39: =SUM(D39:F47) -> 0 | H39: =H38+G39 -> 231 | I39: =IF(T_T1346[[#This Row],[Total]]<0,T_T1346[[#This Row],[Total]]*-1,0) -> 0
I40: =IF(T_T1346[[#This Row],[Total]]<0,T_T1346[[#This Row],[Total]]*-1,0) -> 0
I41: =IF(T_T1346[[#This Row],[Total]]<0,T_T1346[[#This Row],[Total]]*-1,0) -> 0

Sheet LOCAL 07
A2: Departamento : | B2: LOCAL 07
A3: Propietario : | B3: =LOOKUP(B2,#REF!,#REF!) -> #REF!
A4: Inquilino : | B4: =LOOKUP(B2,#REF!,#REF!) -> #REF!
A5: Teléfono : | B5: =LOOKUP(B2,#REF!,#REF!) -> #REF!
A6: Celular : | B6: =LOOKUP(B2,#REF!,#REF!) -> #REF!
A7: Inquilino : | B7: =LOOKUP(B2,#REF!,#REF!) -> #REF! | H7: Resumen
A9: Fecha | B9: Concepto | C9: Recibo | D9: Expensas | E9: Agua | F9: Multa | G9: Total | H9: Deuda | I9: Pagado | J9: Columna1
B10: DEUDA GESTION 2017-2020 | H10: 0 | I10: =IF(T_T1347[[#This Row],[Total]]<0,T_T1347[[#This Row],[Total]]*-1,0) -> 0
B11: DEUDA GESTION 2021 | H11: 0 | I11: =IF(T_T1347[[#This Row],[Total]]<0,T_T1347[[#This Row],[Total]]*-1,0) -> 0
B12: DEUDA GESTION 2022 | H12: 0 | I12: =IF(T_T1347[[#This Row],[Total]]<0,T_T1347[[#This Row],[Total]]*-1,0) -> 0
B13: DEUDA GESTION 2023 | H13: 0 | I13: =IF(T_T1347[[#This Row],[Total]]<0,T_T1347[[#This Row],[Total]]*-1,0) -> 0
B14: DEUDA GESTION 2024 | I14: =IF(T_T1347[[#This Row],[Total]]<0,T_T1347[[#This Row],[Total]]*-1,0) -> 0
A15: 46052 | B15: Mantenimiento enero/2026 | D15: 74 | E15: 13 | G15: =SUM(D15:F15) -> 87 | H15: =+H13+T_T1347[[#This Row],[Total]] -> 87 | I15: =IF(T_T1347[[#This Row],[Total]]<0,T_T1347[[#This Row],[Total]]*-1,0) -> 0
B16: Pago mantenimiento enero/2026 | G16: =SUM(D16:F16) -> 0 | H16: =H15+G16 -> 87 | I16: =IF(T_T1347[[#This Row],[Total]]<0,T_T1347[[#This Row],[Total]]*-1,0) -> 0
A17: 45715 | B17: Mantenimiento febrero/2025 | D17: 74 | E17: 13 | G17: =SUM(D17:F17) -> 87 | H17: =H16+G17 -> 174 | I17: =IF(T_T1347[[#This Row],[Total]]<0,T_T1347[[#This Row],[Total]]*-1,0) -> 0
B18: Pago mantenimiento febrero/2025 | G18: =SUM(D18:F18) -> 0 | H18: =H17+G18 -> 174 | I18: =IF(T_T1347[[#This Row],[Total]]<0,T_T1347[[#This Row],[Total]]*-1,0) -> 0
A19: 45747 | B19: Mantenimiento marzo/2025 | D19: 89 | E19: 13 | G19: =SUM(D19:F19) -> 102 | H19: =H18+G19 -> 276 | I19: =IF(T_T1347[[#This Row],[Total]]<0,T_T1347[[#This Row],[Total]]*-1,0) -> 0
B20: Pago matenimiento marzo/2025 | G20: =SUM(D20:F20) -> 0 | H20: =H19+G20 -> 276 | I20: =IF(T_T1347[[#This Row],[Total]]<0,T_T1347[[#This Row],[Total]]*-1,0) -> 0
A21: 45777 | B21: Mantenimiento abril/2025 | D21: 89 | E21: 13 | G21: =SUM(D21:F21) -> 102 | H21: =H20+G21 -> 378 | I21: =IF(T_T1347[[#This Row],[Total]]<0,T_T1347[[#This Row],[Total]]*-1,0) -> 0
B22: Pago mantenimiento abril/2025 | G22: =SUM(D22:F22) -> 0 | H22: =H21+G22 -> 378 | I22: =IF(T_T1347[[#This Row],[Total]]<0,T_T1347[[#This Row],[Total]]*-1,0) -> 0
A23: 45807 | B23: Mantenimiento mayo/2025 | D23: 89 | E23: 13 | G23: =SUM(D23:F23) -> 102 | H23: =H22+G23 -> 480 | I23: =IF(T_T1347[[#This Row],[Total]]<0,T_T1347[[#This Row],[Total]]*-1,0) -> 0
B24: Pago mantenimiento mayo/2025 | G24: =SUM(D24:F24) -> 0 | H24: =H23+G24 -> 480 | I24: =IF(T_T1347[[#This Row],[Total]]<0,T_T1347[[#This Row],[Total]]*-1,0) -> 0
A25: 45838 | B25: Mantenimiento junio/2025 | G25: =SUM(D25:F25) -> 0 | H25: =H24+G25 -> 480 | I25: =IF(T_T1347[[#This Row],[Total]]<0,T_T1347[[#This Row],[Total]]*-1,0) -> 0
B26: Pago mantenimiento junio/2025 | G26: =SUM(D26:F26) -> 0 | H26: =H25+G26 -> 480 | I26: =IF(T_T1347[[#This Row],[Total]]<0,T_T1347[[#This Row],[Total]]*-1,0) -> 0
A27: 45868 | B27: Mantenimiento julio/2025 | G27: =SUM(D27:F27) -> 0 | H27: =H26+G27 -> 480 | I27: =IF(T_T1347[[#This Row],[Total]]<0,T_T1347[[#This Row],[Total]]*-1,0) -> 0
B28: Pago mantenimient julio/2025 | G28: =SUM(D28:F28) -> 0 | H28: =H27+G28 -> 480 | I28: =IF(T_T1347[[#This Row],[Total]]<0,T_T1347[[#This Row],[Total]]*-1,0) -> 0
A29: 45899 | B29: Mantenimiento agosto/2025 | G29: =SUM(D29:F29) -> 0 | H29: =H28+G29 -> 480 | I29: =IF(T_T1347[[#This Row],[Total]]<0,T_T1347[[#This Row],[Total]]*-1,0) -> 0
B30: Pago mantenimiento agosto/2025 | G30: =SUM(D30:F30) -> 0 | H30: =H29+G30 -> 480 | I30: =IF(T_T1347[[#This Row],[Total]]<0,T_T1347[[#This Row],[Total]]*-1,0) -> 0
A31: 45930 | B31: Mantenimiento septiembre/2025 | G31: =SUM(D31:F31) -> 0 | H31: =H30+G31 -> 480 | I31: =IF(T_T1347[[#This Row],[Total]]<0,T_T1347[[#This Row],[Total]]*-1,0) -> 0
B32: Pago mantenimiento septiembre/2025 | G32: =SUM(D32:F32) -> 0 | H32: =H31+G32 -> 480 | I32: =IF(T_T1347[[#This Row],[Total]]<0,T_T1347[[#This Row],[Total]]*-1,0) -> 0
A33: 45960 | B33: Mantenimiento octubre /2025 | G33: =SUM(D33:F33) -> 0 | H33: =H32+G33 -> 480 | I33: =IF(T_T1347[[#This Row],[Total]]<0,T_T1347[[#This Row],[Total]]*-1,0) -> 0
B34: Pago mantenimiento octubre/2025 | G34: =SUM(D34:F34) -> 0 | H34: =H33+G34 -> 480 | I34: =IF(T_T1347[[#This Row],[Total]]<0,T_T1347[[#This Row],[Total]]*-1,0) -> 0
A35: 45991 | B35: Mantenimiento noviembre/2025 | G35: =SUM(D35:F35) -> 0 | H35: =H34+G35 -> 480 | I35: =IF(T_T1347[[#This Row],[Total]]<0,T_T1347[[#This Row],[Total]]*-1,0) -> 0
B36: Pago mantenimiento noviembre/2025 | G36: =SUM(D36:F36) -> 0 | H36: =H35+G36 -> 480 | I36: =IF(T_T1347[[#This Row],[Total]]<0,T_T1347[[#This Row],[Total]]*-1,0) -> 0
A37: 46021 | B37: Mantenimiento diciembre/2025 | G37: =SUM(D37:F37) -> 0 | H37: =H36+G37 -> 480 | I37: =IF(T_T1347[[#This Row],[Total]]<0,T_T1347[[#This Row],[Total]]*-1,0) -> 0
B38: Pago de Mantenimiento diciembre/2025 | G38: =SUM(D38:F38) -> 0 | H38: =H37+G38 -> 480 | I38: =IF(T_T1347[[#This Row],[Total]]<0,T_T1347[[#This Row],[Total]]*-1,0) -> 0
G39: =SUM(D39:F46) -> 0 | H39: =H38+G39 -> 480 | I39: =IF(T_T1347[[#This Row],[Total]]<0,T_T1347[[#This Row],[Total]]*-1,0) -> 0
G40: =SUM(D40:F47) -> 0 | H40: =H39+G40 -> 480 | I40: =IF(T_T1347[[#This Row],[Total]]<0,T_T1347[[#This Row],[Total]]*-1,0) -> 0
G45: =+G42-F46 -> 0
F46: =+C46+D46+E46 -> 0

Sheet lOCAL 8 
B3: Departamento : | C3: LOCAL 08
B5: Fecha | C5: Concepto | D5: Recibo | E5: Expensas | F5: Agua | G5: Multa | H5: Total | I5: Deuda
C6: DEUDA GESTION 2017-2020 | I6: 0
C7: DEUDA GESTION 2021 | I7: 0
C8: DEUDA GESTION 2022 | I8: 0
C9: DEUDA GESTION 2023 | I9: 0
C10: DEUDA GESTION 2024
B11: 46052 | C11: Mantenimiento enero/2026 | E11: 68 | F11: 13 | H11: =SUM(E11:G11) -> 81 | I11: =+I10+H11 -> 81
C12: Pago mantenimiento enero/2026 | D12: 8608 | E12: -68 | F12: -13 | H12: =SUM(E12:G12) -> -81 | I12: =I11+H12 -> 0
B13: 45715 | C13: Mantenimiento febrero/2025 | E13: 68 | F13: 13 | H13: =SUM(E13:G13) -> 81 | I13: =I12+H13 -> 81
C14: Pago mantenimiento febrero/2025 | D14: 8723 | E14: -68 | F14: -13 | H14: =SUM(E14:G14) -> -81 | I14: =I13+H14 -> 0
B15: 45747 | C15: Mantenimiento marzo/2025 | E15: 81 | F15: 13 | H15: =SUM(E15:G15) -> 94 | I15: =I14+H15 -> 94
C16: Pago matenimiento marzo/2025 | D16: 8890 | E16: -81 | F16: -13 | H16: =SUM(E16:G16) -> -94 | I16: =I15+H16 -> 0
B17: 45777 | C17: Mantenimiento abril/2025 | E17: 81 | F17: 13 | H17: =SUM(E17:G17) -> 94 | I17: =I16+H17 -> 94
C18: Pago mantenimiento abril/2025 | D18: 8890 | E18: -81 | F18: -13 | H18: =SUM(E18:G18) -> -94 | I18: =I17+H18 -> 0
B19: 45807 | C19: Mantenimiento mayo/2025 | E19: 81 | F19: 13 | H19: =SUM(E19:G19) -> 94 | I19: =I18+H19 -> 94
C20: Pago mantenimiento mayo/2025 | H20: =SUM(E20:G20) -> 0 | I20: =I19+H20 -> 94
B21: 45838 | C21: Mantenimiento junio/2025 | H21: =SUM(E21:G21) -> 0 | I21: =I20+H21 -> 94
C22: Pago mantenimiento junio/2025 | H22: =SUM(E22:G22) -> 0 | I22: =I21+H22 -> 94
B23: 45868 | C23: Mantenimiento julio/2025 | H23: =SUM(E23:G23) -> 0 | I23: =I22+H23 -> 94
C24: Pago mantenimient julio/2025 | H24: =SUM(E24:G24) -> 0 | I24: =I23+H24 -> 94
B25: 45899 | C25: Mantenimiento agosto/2025 | H25: =SUM(E25:G25) -> 0 | I25: =I24+H25 -> 94
C26: Pago mantenimiento agosto/2025 | H26: =SUM(E26:G26) -> 0 | I26: =I25+H26 -> 94
B27: 45930 | C27: Mantenimiento septiembre/2025 | H27: =SUM(E27:G27) -> 0 | I27: =I26+H27 -> 94
C28: Pago mantenimiento septiembre/2025 | H28: =SUM(E28:G28) -> 0 | I28: =I27+H28 -> 94
B29: 45960 | C29: Mantenimiento octubre /2025 | H29: =SUM(E29:G29) -> 0 | I29: =I28+H29 -> 94
C30: Pago mantenimiento octubre/2025 | H30: =SUM(E30:G30) -> 0 | I30: =I29+H30 -> 94
B31: 45991 | C31: Mantenimiento noviembre/2025 | H31: =SUM(E31:G31) -> 0 | I31: =I30+H31 -> 94
C32: Pago mantenimiento noviembre/2025 | H32: =SUM(E32:G32) -> 0 | I32: =I31+H32 -> 94
B33: 46021 | C33: Mantenimiento diciembre/2025 | H33: =SUM(E33:G33) -> 0 | I33: =I32+H33 -> 94
C34: Pago de Mantenimiento diciembre/2025 | H34: =SUM(E34:G34) -> 0 | I34: =I33+H34 -> 94
H35: =SUM(E35:G43) -> 0 | I35: =I34+H35 -> 94

Sheet LOCAL 09
A2: Departamento : | B2: LOCAL 09
A3: Propietario : | B3: =LOOKUP(B2,#REF!,#REF!) -> #REF!
A4: Inquilino : | B4: =LOOKUP(B2,#REF!,#REF!) -> #REF!
A5: Teléfono : | B5: =LOOKUP(B2,#REF!,#REF!) -> #REF!
A6: Celular : | B6: =LOOKUP(B2,#REF!,#REF!) -> #REF!
A7: Correo : | B7: =LOOKUP(B2,#REF!,#REF!) -> #REF! | H7: Resumen
B8: EVA LUCIANA ZEGARRA
A9: Fecha | B9: Concepto | C9: Recibo | D9: Expensas | E9: Agua | F9: Multa | G9: Total | H9: Deuda | I9: Pagado | J9: Columna1
B10: DEUDA GESTION 2017-2020 | H10: 0 | I10: =IF(T_T1349[[#This Row],[Total]]<0,T_T1349[[#This Row],[Total]]*-1,0) -> 0
B11: DEUDA GESTION 2021 | H11: 0 | I11: =IF(T_T1349[[#This Row],[Total]]<0,T_T1349[[#This Row],[Total]]*-1,0) -> 0
B12: DEUDA GESTION 2022 | H12: 0 | I12: =IF(T_T1349[[#This Row],[Total]]<0,T_T1349[[#This Row],[Total]]*-1,0) -> 0
B13: DEUDA GESTION 2023 | H13: 0 | I13: =IF(T_T1349[[#This Row],[Total]]<0,T_T1349[[#This Row],[Total]]*-1,0) -> 0
B14: DEUDA GESTION 2024 | I14: =IF(T_T1349[[#This Row],[Total]]<0,T_T1349[[#This Row],[Total]]*-1,0) -> 0
A15: 46052 | B15: Mantenimiento enero/2026 | D15: 75 | E15: 13 | G15: =SUM(D15:F15) -> 88 | H15: =+H13+H10+H11+H12+T_T1349[[#This Row],[Total]] -> 88 | I15: =IF(T_T1349[[#This Row],[Total]]<0,T_T1349[[#This Row],[Total]]*-1,0) -> 0 | L15: VIOLETA PARRA
B16: Pago mantenimiento enero/2026 | C16: 8754 | D16: -75 | E16: -13 | G16: =SUM(D16:F16) -> -88 | H16: =H15+G16 -> 0 | I16: =IF(T_T1349[[#This Row],[Total]]<0,T_T1349[[#This Row],[Total]]*-1,0) -> 88
A17: 46081 | B17: Mantenimiento febrero/2026 | D17: 75 | E17: 13 | G17: =SUM(D17:F17) -> 88 | H17: =H16+G17 -> 88 | I17: =IF(T_T1349[[#This Row],[Total]]<0,T_T1349[[#This Row],[Total]]*-1,0) -> 0
B18: Pago mantenimiento febrero/2026 | G18: =SUM(D18:F18) -> 0 | H18: =H17+G18 -> 88 | I18: =IF(T_T1349[[#This Row],[Total]]<0,T_T1349[[#This Row],[Total]]*-1,0) -> 0
A19: 45747 | B19: Mantenimiento marzo/2025 | D19: 90 | E19: 13 | G19: =SUM(D19:F19) -> 103 | H19: =H18+G19 -> 191 | I19: =IF(T_T1349[[#This Row],[Total]]<0,T_T1349[[#This Row],[Total]]*-1,0) -> 0
B20: Pago matenimiento marzo/2025 | G20: =SUM(D20:F20) -> 0 | H20: =H19+G20 -> 191 | I20: =IF(T_T1349[[#This Row],[Total]]<0,T_T1349[[#This Row],[Total]]*-1,0) -> 0
A21: 45777 | B21: Mantenimiento abril/2025 | D21: 90 | E21: 13 | G21: =SUM(D21:F21) -> 103 | H21: =H20+G21 -> 294 | I21: =IF(T_T1349[[#This Row],[Total]]<0,T_T1349[[#This Row],[Total]]*-1,0) -> 0
B22: Pago mantenimiento abril/2025 | G22: =SUM(D22:F22) -> 0 | H22: =H21+G22 -> 294 | I22: =IF(T_T1349[[#This Row],[Total]]<0,T_T1349[[#This Row],[Total]]*-1,0) -> 0
A23: 45807 | B23: Mantenimiento mayo/2025 | D23: 90 | E23: 13 | G23: =SUM(D23:F23) -> 103 | H23: =H22+G23 -> 397 | I23: =IF(T_T1349[[#This Row],[Total]]<0,T_T1349[[#This Row],[Total]]*-1,0) -> 0
B24: Pago mantenimiento mayo/2025 | G24: =SUM(D24:F24) -> 0 | H24: =H23+G24 -> 397 | I24: =IF(T_T1349[[#This Row],[Total]]<0,T_T1349[[#This Row],[Total]]*-1,0) -> 0
A25: 45838 | B25: Mantenimiento junio/2025 | G25: =SUM(D25:F25) -> 0 | H25: =H24+G25 -> 397 | I25: =IF(T_T1349[[#This Row],[Total]]<0,T_T1349[[#This Row],[Total]]*-1,0) -> 0
B26: Pago mantenimiento junio/2025 | G26: =SUM(D26:F26) -> 0 | H26: =H25+G26 -> 397 | I26: =IF(T_T1349[[#This Row],[Total]]<0,T_T1349[[#This Row],[Total]]*-1,0) -> 0
A27: 45868 | B27: Mantenimiento julio/2025 | G27: =SUM(D27:F27) -> 0 | H27: =H26+G27 -> 397 | I27: =IF(T_T1349[[#This Row],[Total]]<0,T_T1349[[#This Row],[Total]]*-1,0) -> 0
B28: Pago mantenimient julio/2025 | G28: =SUM(D28:F28) -> 0 | H28: =H27+G28 -> 397 | I28: =IF(T_T1349[[#This Row],[Total]]<0,T_T1349[[#This Row],[Total]]*-1,0) -> 0
A29: 45899 | B29: Mantenimiento agosto/2025 | G29: =SUM(D29:F29) -> 0 | H29: =H28+G29 -> 397 | I29: =IF(T_T1349[[#This Row],[Total]]<0,T_T1349[[#This Row],[Total]]*-1,0) -> 0
B30: Pago mantenimiento agosto/2025 | G30: =SUM(D30:F30) -> 0 | H30: =H29+G30 -> 397 | I30: =IF(T_T1349[[#This Row],[Total]]<0,T_T1349[[#This Row],[Total]]*-1,0) -> 0
A31: 45930 | B31: Mantenimiento septiembre/2025 | G31: =SUM(D31:F31) -> 0 | H31: =H30+G31 -> 397 | I31: =IF(T_T1349[[#This Row],[Total]]<0,T_T1349[[#This Row],[Total]]*-1,0) -> 0
B32: Pago mantenimiento septiembre/2025 | G32: =SUM(D32:F32) -> 0 | H32: =H31+G32 -> 397 | I32: =IF(T_T1349[[#This Row],[Total]]<0,T_T1349[[#This Row],[Total]]*-1,0) -> 0
A33: 45960 | B33: Mantenimiento octubre /2025 | G33: =SUM(D33:F33) -> 0 | H33: =H32+G33 -> 397 | I33: =IF(T_T1349[[#This Row],[Total]]<0,T_T1349[[#This Row],[Total]]*-1,0) -> 0
B34: Pago mantenimiento octubre/2025 | G34: =SUM(D34:F34) -> 0 | H34: =H33+G34 -> 397 | I34: =IF(T_T1349[[#This Row],[Total]]<0,T_T1349[[#This Row],[Total]]*-1,0) -> 0
A35: 45991 | B35: Mantenimiento noviembre/2025 | G35: =SUM(D35:F35) -> 0 | H35: =H34+G35 -> 397 | I35: =IF(T_T1349[[#This Row],[Total]]<0,T_T1349[[#This Row],[Total]]*-1,0) -> 0
B36: Pago mantenimiento noviembre/2025 | G36: =SUM(D36:F36) -> 0 | H36: =H35+G36 -> 397 | I36: =IF(T_T1349[[#This Row],[Total]]<0,T_T1349[[#This Row],[Total]]*-1,0) -> 0
A37: 46021 | B37: Mantenimiento diciembre/2025 | G37: =SUM(D37:F37) -> 0 | H37: =H36+G37 -> 397 | I37: =IF(T_T1349[[#This Row],[Total]]<0,T_T1349[[#This Row],[Total]]*-1,0) -> 0
B38: Pago de Mantenimiento diciembre/2025 | G38: =SUM(D38:F38) -> 0 | H38: =H37+G38 -> 397 | I38: =IF(T_T1349[[#This Row],[Total]]<0,T_T1349[[#This Row],[Total]]*-1,0) -> 0
G39: =SUM(D39:F47) -> 0 | H39: =H38+G39 -> 397 | I39: =IF(T_T1349[[#This Row],[Total]]<0,T_T1349[[#This Row],[Total]]*-1,0) -> 0
H40: =H39+G40 -> 397 | I40: =IF(T_T1349[[#This Row],[Total]]<0,T_T1349[[#This Row],[Total]]*-1,0) -> 0
H41: =H40+G41 -> 397 | I41: =IF(T_T1349[[#This Row],[Total]]<0,T_T1349[[#This Row],[Total]]*-1,0) -> 0

Sheet LOCAL 10
B3: Departamento : | C3: local 10
B4: Propietario : | C4: MANUEL AJATA
B10: Fecha | C10: Concepto | D10: Recibo | E10: Expensas | F10: Agua | G10: Multa | H10: Total | I10: Deuda
C11: DEUDA GESTION 2017-2020 | I11: 0
C12: DEUDA GESTION 2021 | I12: 0
C13: DEUDA GESTION 2022 | I13: 0
C14: DEUDA GESTION 2023 | I14: 0
C15: DEUDA GESTION 2024
B16: 46052 | C16: Mantenimiento enero/2026 | E16: 82 | F16: 75 | H16: =SUM(E16:G16) -> 157 | I16: =+I15+H16 -> 157
C17: Pago mantenimiento enero/2026 | D17: 8823 | E17: -82 | F17: -75 | H17: =SUM(E17:G17) -> -157 | I17: =I16+H17 -> 0
B18: 45716 | C18: Mantenimiento febrero/2026 | E18: 82 | F18: 61 | H18: =SUM(E18:G18) -> 143 | I18: =I17+H18 -> 143
C19: Pago mantenimiento febrero/2026 | D19: 8823 | E19: -82 | F19: -61 | H19: =SUM(E19:G19) -> -143 | I19: =I18+H19 -> 0
B20: 45747 | C20: Mantenimiento marzo/2025 | E20: 98 | F20: 54 | H20: =SUM(E20:G20) -> 152 | I20: =I19+H20 -> 152
C21: Pago matenimiento marzo/2025 | D21: 8823 | E21: -98 | F21: -54 | H21: =SUM(E21:G21) -> -152 | I21: =I20+H21 -> 0
B22: 45777 | C22: Mantenimiento abril/2025 | E22: 98 | F22: 57 | H22: =SUM(E22:G22) -> 155 | I22: =I21+H22 -> 155
C23: Pago mantenimiento abril/2025 | D23: 8945 | E23: -98 | F23: -57 | H23: =SUM(E23:G23) -> -155 | I23: =I22+H23 -> 0
B24: 45807 | C24: Mantenimiento mayo/2025 | E24: 98 | F24: 55 | H24: =SUM(E24:G24) -> 153 | I24: =I23+H24 -> 153
C25: Pago mantenimiento mayo/2025 | H25: =SUM(E25:G25) -> 0 | I25: =I24+H25 -> 153
B26: 45838 | C26: Mantenimiento junio/2025 | H26: =SUM(E26:G26) -> 0 | I26: =I25+H26 -> 153
C27: Pago mantenimiento junio/2025 | H27: =SUM(E27:G27) -> 0 | I27: =I26+H27 -> 153
B28: 45868 | C28: Mantenimiento julio/2025 | H28: =SUM(E28:G28) -> 0 | I28: =I27+H28 -> 153
C29: Pago mantenimient julio/2025 | H29: =SUM(E29:G29) -> 0 | I29: =I28+H29 -> 153
B30: 45899 | C30: Mantenimiento agosto/2025 | H30: =SUM(E30:G30) -> 0 | I30: =I29+H30 -> 153
C31: Pago mantenimiento agosto/2025 | H31: =SUM(E31:G31) -> 0 | I31: =I30+H31 -> 153
B32: 45930 | C32: Mantenimiento septiembre/2025 | H32: =SUM(E32:G32) -> 0 | I32: =I31+H32 -> 153
C33: Pago mantenimiento septiembre/2025 | H33: =SUM(E33:G33) -> 0 | I33: =I32+H33 -> 153
B34: 45960 | C34: Mantenimiento octubre /2025 | H34: =SUM(E34:G34) -> 0 | I34: =I33+H34 -> 153
C35: Pago mantenimiento octubre/2025 | H35: =SUM(E35:G35) -> 0 | I35: =I34+H35 -> 153
B36: 45991 | C36: Mantenimiento noviembre/2025 | H36: =SUM(E36:G36) -> 0 | I36: =I35+H36 -> 153
C37: Pago mantenimiento noviembre/2025 | H37: =SUM(E37:G37) -> 0 | I37: =I36+H37 -> 153
B38: 46021 | C38: Mantenimiento diciembre/2025 | H38: =SUM(E38:G38) -> 0 | I38: =I37+H38 -> 153
C39: Pago de Mantenimiento diciembre/2025 | H39: =SUM(E39:G39) -> 0 | I39: =I38+H39 -> 153
H40: =SUM(E40:G40) -> 0 | I40: =I39+H40 -> 153

Sheet LOCAL.11
A2: Departamento : | B2: LOCAL 11
A3: Propietario : | B3: FELIX RAMIREZ
A4: Inquilino : | B4: =LOOKUP(B2,#REF!,#REF!) -> #REF!
A5: Teléfono : | B5: =LOOKUP(B2,#REF!,#REF!) -> #REF!
A6: Celular : | B6: =LOOKUP(B2,#REF!,#REF!) -> #REF!
A7: Correo : | B7: =LOOKUP(B2,#REF!,#REF!) -> #REF! | H7: Resumen
B8: FRESIA C. FLORES
A9: Fecha | B9: Concepto | C9: Recibo | D9: Expensas | E9: Agua | F9: Multa | G9: Total | H9: Deuda | I9: Pagado | J9: Columna1 | K9: Columna2
B10: DEUDA GESTION 2017-2020 | H10: 0 | I10: =IF(T_T1341112131415161718[[#This Row],[Total]]<0,T_T1341112131415161718[[#This Row],[Total]]*-1,0) -> 0 | M10: 300
B11: DEUDA GESTION 2021 | H11: 0 | I11: =IF(T_T1341112131415161718[[#This Row],[Total]]<0,T_T1341112131415161718[[#This Row],[Total]]*-1,0) -> 0
B12: DEUDA GESTION 2022 | H12: 0 | I12: =IF(T_T1341112131415161718[[#This Row],[Total]]<0,T_T1341112131415161718[[#This Row],[Total]]*-1,0) -> 0
B13: DEUDA GESTION 2023 | H13: 0 | I13: =IF(T_T1341112131415161718[[#This Row],[Total]]<0,T_T1341112131415161718[[#This Row],[Total]]*-1,0) -> 0
B14: DEUDA GESTION 2024 | I14: =IF(T_T1341112131415161718[[#This Row],[Total]]<0,T_T1341112131415161718[[#This Row],[Total]]*-1,0) -> 0
A15: 46052 | B15: Mantenimiento enero/2026 | D15: 69 | E15: 5 | G15: =SUM(D15:F15) -> 74 | H15: =+H13+T_T1341112131415161718[[#This Row],[Total]]+H10 -> 74 | I15: =IF(T_T1341112131415161718[[#This Row],[Total]]<0,T_T1341112131415161718[[#This Row],[Total]]*-1,0) -> 0
B16: Pago mantenimiento enero/2026 | C16: 8578 | D16: -69 | E16: -5 | G16: =SUM(D16:F16) -> -74 | H16: =H15+G16 -> 0 | I16: =IF(T_T1341112131415161718[[#This Row],[Total]]<0,T_T1341112131415161718[[#This Row],[Total]]*-1,0) -> 74
A17: 46080 | B17: Mantenimiento febrero/2026 | D17: 69 | E17: 5 | G17: =SUM(D17:F17) -> 74 | H17: =H16+G17 -> 74 | I17: =IF(T_T1341112131415161718[[#This Row],[Total]]<0,T_T1341112131415161718[[#This Row],[Total]]*-1,0) -> 0
B18: Pago mantenimiento febrero/2026 | C18: 8720 | D18: -69 | E18: -5 | G18: =SUM(D18:F18) -> -74 | H18: =H17+G18 -> 0 | I18: =IF(T_T1341112131415161718[[#This Row],[Total]]<0,T_T1341112131415161718[[#This Row],[Total]]*-1,0) -> 74
A19: 45747 | B19: Mantenimiento marzo/2025 | D19: 83 | E19: 5 | G19: =SUM(D19:F19) -> 88 | H19: =H18+G19 -> 88 | I19: =IF(T_T1341112131415161718[[#This Row],[Total]]<0,T_T1341112131415161718[[#This Row],[Total]]*-1,0) -> 0
B20: Pago matenimiento marzo/2025 | C20: 8830 | D20: -83 | E20: -5 | G20: =SUM(D20:F20) -> -88 | H20: =H19+G20 -> 0 | I20: =IF(T_T1341112131415161718[[#This Row],[Total]]<0,T_T1341112131415161718[[#This Row],[Total]]*-1,0) -> 88
A21: 45777 | B21: Mantenimiento abril/2025 | D21: 83 | E21: 5 | G21: =SUM(D21:F21) -> 88 | H21: =H20+G21 -> 88 | I21: =IF(T_T1341112131415161718[[#This Row],[Total]]<0,T_T1341112131415161718[[#This Row],[Total]]*-1,0) -> 0
B22: Pago mantenimiento abril/2025 | C22: 8953 | D22: -83 | E22: -5 | G22: =SUM(D22:F22) -> -88 | H22: =H21+G22 -> 0 | I22: =IF(T_T1341112131415161718[[#This Row],[Total]]<0,T_T1341112131415161718[[#This Row],[Total]]*-1,0) -> 88
A23: 45807 | B23: Mantenimiento mayo/2025 | D23: 83 | E23: 10 | G23: =SUM(D23:F23) -> 93 | H23: =H22+G23 -> 93 | I23: =IF(T_T1341112131415161718[[#This Row],[Total]]<0,T_T1341112131415161718[[#This Row],[Total]]*-1,0) -> 0
B24: Pago mantenimiento mayo/2025 | G24: =SUM(D24:F24) -> 0 | H24: =H23+G24 -> 93 | I24: =IF(T_T1341112131415161718[[#This Row],[Total]]<0,T_T1341112131415161718[[#This Row],[Total]]*-1,0) -> 0
A25: 45838 | B25: Mantenimiento junio/2025 | G25: =SUM(D25:F25) -> 0 | H25: =H24+G25 -> 93 | I25: =IF(T_T1341112131415161718[[#This Row],[Total]]<0,T_T1341112131415161718[[#This Row],[Total]]*-1,0) -> 0
B26: Pago mantenimiento junio/2025 | G26: =SUM(D26:F26) -> 0 | H26: =H25+G26 -> 93 | I26: =IF(T_T1341112131415161718[[#This Row],[Total]]<0,T_T1341112131415161718[[#This Row],[Total]]*-1,0) -> 0
A27: 45868 | B27: Mantenimiento julio/2025 | G27: =SUM(D27:F27) -> 0 | H27: =H26+G27 -> 93 | I27: =IF(T_T1341112131415161718[[#This Row],[Total]]<0,T_T1341112131415161718[[#This Row],[Total]]*-1,0) -> 0
B28: Pago mantenimient julio/2025 | G28: =SUM(D28:F28) -> 0 | H28: =H27+G28 -> 93 | I28: =IF(T_T1341112131415161718[[#This Row],[Total]]<0,T_T1341112131415161718[[#This Row],[Total]]*-1,0) -> 0
A29: 45899 | B29: Mantenimiento agosto/2025 | G29: =SUM(D29:F29) -> 0 | H29: =H28+G29 -> 93 | I29: =IF(T_T1341112131415161718[[#This Row],[Total]]<0,T_T1341112131415161718[[#This Row],[Total]]*-1,0) -> 0
B30: Pago mantenimiento agosto/2025 | G30: =SUM(D30:F30) -> 0 | H30: =H29+G30 -> 93 | I30: =IF(T_T1341112131415161718[[#This Row],[Total]]<0,T_T1341112131415161718[[#This Row],[Total]]*-1,0) -> 0
A31: 45930 | B31: Mantenimiento septiembre/2025 | G31: =SUM(D31:F31) -> 0 | H31: =H30+G31 -> 93 | I31: =IF(T_T1341112131415161718[[#This Row],[Total]]<0,T_T1341112131415161718[[#This Row],[Total]]*-1,0) -> 0
